<?xml version="1.0" encoding="utf-8"?><testsuites name="pytest tests"><testsuite name="pytest" errors="1" failures="0" skipped="0" tests="1" time="1.105" timestamp="2025-08-29T19:37:46.655456+02:00" hostname="IFL-NB-80"><testcase classname="pytest" name="internal" time="0.000"><error message="internal error">Traceback (most recent call last):
  File "c:\GitHub\clausemate\tests\test_coverage.py", line 7, in &lt;module&gt;
    from main import ClauseMateAnalyzer
  File "c:\GitHub\clausemate\src\main.py", line 12, in &lt;module&gt;
    from .config import FilePaths
ImportError: attempted relative import with no known parent package

During handling of the above exception, another exception occurred:

Traceback (most recent call last):
  File "c:\GitHub\clausemate\.venv\Lib\site-packages\_pytest\main.py", line 289, in wrap_session
    session.exitstatus = doit(config, session) or 0
                         ~~~~^^^^^^^^^^^^^^^^^
  File "c:\GitHub\clausemate\.venv\Lib\site-packages\_pytest\main.py", line 342, in _main
    config.hook.pytest_collection(session=session)
    ~~~~~~~~~~~~~~~~~~~~~~~~~~~~~^^^^^^^^^^^^^^^^^
  File "c:\GitHub\clausemate\.venv\Lib\site-packages\pluggy\_hooks.py", line 512, in __call__
    return self._hookexec(self.name, self._hookimpls.copy(), kwargs, firstresult)
           ~~~~~~~~~~~~~~^^^^^^^^^^^^^^^^^^^^^^^^^^^^^^^^^^^^^^^^^^^^^^^^^^^^^^^^
  File "c:\GitHub\clausemate\.venv\Lib\site-packages\pluggy\_manager.py", line 120, in _hookexec
    return self._inner_hookexec(hook_name, methods, kwargs, firstresult)
           ~~~~~~~~~~~~~~~~~~~~^^^^^^^^^^^^^^^^^^^^^^^^^^^^^^^^^^^^^^^^^
  File "c:\GitHub\clausemate\.venv\Lib\site-packages\pluggy\_callers.py", line 167, in _multicall
    raise exception
  File "c:\GitHub\clausemate\.venv\Lib\site-packages\pluggy\_callers.py", line 139, in _multicall
    teardown.throw(exception)
    ~~~~~~~~~~~~~~^^^^^^^^^^^
  File "c:\GitHub\clausemate\.venv\Lib\site-packages\_pytest\logging.py", line 788, in pytest_collection
    return (yield)
            ^^^^^
  File "c:\GitHub\clausemate\.venv\Lib\site-packages\pluggy\_callers.py", line 139, in _multicall
    teardown.throw(exception)
    ~~~~~~~~~~~~~~^^^^^^^^^^^
  File "c:\GitHub\clausemate\.venv\Lib\site-packages\_pytest\warnings.py", line 99, in pytest_collection
    return (yield)
            ^^^^^
  File "c:\GitHub\clausemate\.venv\Lib\site-packages\pluggy\_callers.py", line 139, in _multicall
    teardown.throw(exception)
    ~~~~~~~~~~~~~~^^^^^^^^^^^
  File "c:\GitHub\clausemate\.venv\Lib\site-packages\_pytest\config\__init__.py", line 1450, in pytest_collection
    return (yield)
            ^^^^^
  File "c:\GitHub\clausemate\.venv\Lib\site-packages\pluggy\_callers.py", line 121, in _multicall
    res = hook_impl.function(*args)
  File "c:\GitHub\clausemate\.venv\Lib\site-packages\_pytest\main.py", line 353, in pytest_collection
    session.perform_collect()
    ~~~~~~~~~~~~~~~~~~~~~~~^^
  File "c:\GitHub\clausemate\.venv\Lib\site-packages\_pytest\main.py", line 813, in perform_collect
    self.items.extend(self.genitems(node))
    ~~~~~~~~~~~~~~~~~^^^^^^^^^^^^^^^^^^^^^
  File "c:\GitHub\clausemate\.venv\Lib\site-packages\_pytest\main.py", line 979, in genitems
    yield from self.genitems(subnode)
  File "c:\GitHub\clausemate\.venv\Lib\site-packages\_pytest\main.py", line 974, in genitems
    rep, duplicate = self._collect_one_node(node, handle_dupes)
                     ~~~~~~~~~~~~~~~~~~~~~~^^^^^^^^^^^^^^^^^^^^
  File "c:\GitHub\clausemate\.venv\Lib\site-packages\_pytest\main.py", line 839, in _collect_one_node
    rep = collect_one_node(node)
  File "c:\GitHub\clausemate\.venv\Lib\site-packages\_pytest\runner.py", line 567, in collect_one_node
    rep: CollectReport = ihook.pytest_make_collect_report(collector=collector)
                         ~~~~~~~~~~~~~~~~~~~~~~~~~~~~~~~~^^^^^^^^^^^^^^^^^^^^^
  File "c:\GitHub\clausemate\.venv\Lib\site-packages\pluggy\_hooks.py", line 512, in __call__
    return self._hookexec(self.name, self._hookimpls.copy(), kwargs, firstresult)
           ~~~~~~~~~~~~~~^^^^^^^^^^^^^^^^^^^^^^^^^^^^^^^^^^^^^^^^^^^^^^^^^^^^^^^^
  File "c:\GitHub\clausemate\.venv\Lib\site-packages\pluggy\_manager.py", line 120, in _hookexec
    return self._inner_hookexec(hook_name, methods, kwargs, firstresult)
           ~~~~~~~~~~~~~~~~~~~~^^^^^^^^^^^^^^^^^^^^^^^^^^^^^^^^^^^^^^^^^
  File "c:\GitHub\clausemate\.venv\Lib\site-packages\pluggy\_callers.py", line 167, in _multicall
    raise exception
  File "c:\GitHub\clausemate\.venv\Lib\site-packages\pluggy\_callers.py", line 139, in _multicall
    teardown.throw(exception)
    ~~~~~~~~~~~~~~^^^^^^^^^^^
  File "c:\GitHub\clausemate\.venv\Lib\site-packages\_pytest\capture.py", line 880, in pytest_make_collect_report
    rep = yield
          ^^^^^
  File "c:\GitHub\clausemate\.venv\Lib\site-packages\pluggy\_callers.py", line 121, in _multicall
    res = hook_impl.function(*args)
  File "c:\GitHub\clausemate\.venv\Lib\site-packages\_pytest\runner.py", line 391, in pytest_make_collect_report
    call = CallInfo.from_call(
        collect, "collect", reraise=(KeyboardInterrupt, SystemExit)
    )
  File "c:\GitHub\clausemate\.venv\Lib\site-packages\_pytest\runner.py", line 344, in from_call
    result: TResult | None = func()
                             ~~~~^^
  File "c:\GitHub\clausemate\.venv\Lib\site-packages\_pytest\runner.py", line 389, in collect
    return list(collector.collect())
                ~~~~~~~~~~~~~~~~~^^
  File "c:\GitHub\clausemate\.venv\Lib\site-packages\_pytest\python.py", line 554, in collect
    self._register_setup_module_fixture()
    ~~~~~~~~~~~~~~~~~~~~~~~~~~~~~~~~~~~^^
  File "c:\GitHub\clausemate\.venv\Lib\site-packages\_pytest\python.py", line 567, in _register_setup_module_fixture
    self.obj, ("setUpModule", "setup_module")
    ^^^^^^^^
  File "c:\GitHub\clausemate\.venv\Lib\site-packages\_pytest\python.py", line 280, in obj
    self._obj = obj = self._getobj()
                      ~~~~~~~~~~~~^^
  File "c:\GitHub\clausemate\.venv\Lib\site-packages\_pytest\python.py", line 551, in _getobj
    return importtestmodule(self.path, self.config)
  File "c:\GitHub\clausemate\.venv\Lib\site-packages\_pytest\python.py", line 498, in importtestmodule
    mod = import_path(
        path,
    ...&lt;2 lines&gt;...
        consider_namespace_packages=config.getini("consider_namespace_packages"),
    )
  File "c:\GitHub\clausemate\.venv\Lib\site-packages\_pytest\pathlib.py", line 587, in import_path
    importlib.import_module(module_name)
    ~~~~~~~~~~~~~~~~~~~~~~~^^^^^^^^^^^^^
  File "C:\Python313\Lib\importlib\__init__.py", line 88, in import_module
    return _bootstrap._gcd_import(name[level:], package, level)
           ~~~~~~~~~~~~~~~~~~~~~~^^^^^^^^^^^^^^^^^^^^^^^^^^^^^^
  File "&lt;frozen importlib._bootstrap&gt;", line 1387, in _gcd_import
  File "&lt;frozen importlib._bootstrap&gt;", line 1360, in _find_and_load
  File "&lt;frozen importlib._bootstrap&gt;", line 1331, in _find_and_load_unlocked
  File "&lt;frozen importlib._bootstrap&gt;", line 935, in _load_unlocked
  File "c:\GitHub\clausemate\.venv\Lib\site-packages\_pytest\assertion\rewrite.py", line 186, in exec_module
    exec(co, module.__dict__)
    ~~~~^^^^^^^^^^^^^^^^^^^^^
  File "c:\GitHub\clausemate\tests\test_coverage.py", line 21, in &lt;module&gt;
    sys.exit(1)
    ~~~~~~~~^^^
SystemExit: 1</error></testcase></testsuite></testsuites>